Freezing layer 'model.22.dfl.conv.weight'
[34m[1mAMP: [0mrunning Automatic Mixed Precision (AMP) checks...
[34m[1mAMP: [0mchecks passed ✅
[34m[1mtrain: [0mScanning C:\Users\Sai\Documents\Neu\Masters_Project\PerceptionPrivacy\datasets\yolo_lp_screen_id\labels\train.cache... 30448 images, 0 backgrounds, 0 corrupt: 100%|██████████| 30448/30448 [00:00<?, ?it/s][0m
[34m[1mtrain: [0m36.5GB RAM required to cache images with 50% safety margin but only 17.7/31.9GB available, not caching images ⚠️
Traceback (most recent call last):
  File "<string>", line 1, in <module>
  File "C:\Users\Sai\AppData\Local\Programs\Python\Python311\Lib\multiprocessing\spawn.py", line 122, in spawn_main
    exitcode = _main(fd, parent_sentinel)
               ^^^^^^^^^^^^^^^^^^^^^^^^^^
  File "C:\Users\Sai\AppData\Local\Programs\Python\Python311\Lib\multiprocessing\spawn.py", line 131, in _main
    prepare(preparation_data)
  File "C:\Users\Sai\AppData\Local\Programs\Python\Python311\Lib\multiprocessing\spawn.py", line 246, in prepare
    _fixup_main_from_path(data['init_main_from_path'])
  File "C:\Users\Sai\AppData\Local\Programs\Python\Python311\Lib\multiprocessing\spawn.py", line 297, in _fixup_main_from_path
    main_content = runpy.run_path(main_path,
                   ^^^^^^^^^^^^^^^^^^^^^^^^^
  File "<frozen runpy>", line 291, in run_path
  File "<frozen runpy>", line 98, in _run_module_code
  File "<frozen runpy>", line 88, in _run_code
  File "c:\Users\Sai\Documents\Neu\Masters_Project\PerceptionPrivacy\instance_segmentation\yolov8-seg\yolov8-seg-train.py", line 7, in <module>
    model.train(
  File "C:\Users\Sai\AppData\Local\Programs\Python\Python311\Lib\site-packages\ultralytics\engine\model.py", line 791, in train
    self.trainer.train()
  File "C:\Users\Sai\AppData\Local\Programs\Python\Python311\Lib\site-packages\ultralytics\engine\trainer.py", line 211, in train
    self._do_train(world_size)
  File "C:\Users\Sai\AppData\Local\Programs\Python\Python311\Lib\site-packages\ultralytics\engine\trainer.py", line 326, in _do_train
    self._setup_train(world_size)
  File "C:\Users\Sai\AppData\Local\Programs\Python\Python311\Lib\site-packages\ultralytics\engine\trainer.py", line 290, in _setup_train
    self.train_loader = self.get_dataloader(self.trainset, batch_size=batch_size, rank=LOCAL_RANK, mode="train")
                        ^^^^^^^^^^^^^^^^^^^^^^^^^^^^^^^^^^^^^^^^^^^^^^^^^^^^^^^^^^^^^^^^^^^^^^^^^^^^^^^^^^^^^^^^
  File "C:\Users\Sai\AppData\Local\Programs\Python\Python311\Lib\site-packages\ultralytics\models\yolo\detect\train.py", line 88, in get_dataloader
    return build_dataloader(dataset, batch_size, workers, shuffle, rank)  # return dataloader
           ^^^^^^^^^^^^^^^^^^^^^^^^^^^^^^^^^^^^^^^^^^^^^^^^^^^^^^^^^^^^^
  File "C:\Users\Sai\AppData\Local\Programs\Python\Python311\Lib\site-packages\ultralytics\data\build.py", line 169, in build_dataloader
    return InfiniteDataLoader(
           ^^^^^^^^^^^^^^^^^^^
  File "C:\Users\Sai\AppData\Local\Programs\Python\Python311\Lib\site-packages\ultralytics\data\build.py", line 50, in __init__
    self.iterator = super().__iter__()
                    ^^^^^^^^^^^^^^^^^^
  File "C:\Users\Sai\AppData\Local\Programs\Python\Python311\Lib\site-packages\torch\utils\data\dataloader.py", line 491, in __iter__
    return self._get_iterator()
           ^^^^^^^^^^^^^^^^^^^^
  File "C:\Users\Sai\AppData\Local\Programs\Python\Python311\Lib\site-packages\torch\utils\data\dataloader.py", line 422, in _get_iterator
    return _MultiProcessingDataLoaderIter(self)
           ^^^^^^^^^^^^^^^^^^^^^^^^^^^^^^^^^^^^
  File "C:\Users\Sai\AppData\Local\Programs\Python\Python311\Lib\site-packages\torch\utils\data\dataloader.py", line 1146, in __init__
    w.start()
  File "C:\Users\Sai\AppData\Local\Programs\Python\Python311\Lib\multiprocessing\process.py", line 121, in start
    self._popen = self._Popen(self)
                  ^^^^^^^^^^^^^^^^^
  File "C:\Users\Sai\AppData\Local\Programs\Python\Python311\Lib\multiprocessing\context.py", line 224, in _Popen
    return _default_context.get_context().Process._Popen(process_obj)
           ^^^^^^^^^^^^^^^^^^^^^^^^^^^^^^^^^^^^^^^^^^^^^^^^^^^^^^^^^^
  File "C:\Users\Sai\AppData\Local\Programs\Python\Python311\Lib\multiprocessing\context.py", line 336, in _Popen
    return Popen(process_obj)
           ^^^^^^^^^^^^^^^^^^
  File "C:\Users\Sai\AppData\Local\Programs\Python\Python311\Lib\multiprocessing\popen_spawn_win32.py", line 46, in __init__
    prep_data = spawn.get_preparation_data(process_obj._name)
                ^^^^^^^^^^^^^^^^^^^^^^^^^^^^^^^^^^^^^^^^^^^^^
  File "C:\Users\Sai\AppData\Local\Programs\Python\Python311\Lib\multiprocessing\spawn.py", line 164, in get_preparation_data
    _check_not_importing_main()
  File "C:\Users\Sai\AppData\Local\Programs\Python\Python311\Lib\multiprocessing\spawn.py", line 140, in _check_not_importing_main
    raise RuntimeError('''
RuntimeError:
        An attempt has been made to start a new process before the
        current process has finished its bootstrapping phase.

        This probably means that you are not using fork to start your
        child processes and you have forgotten to use the proper idiom
        in the main module:

            if __name__ == '__main__':
                freeze_support()
                ...

        The "freeze_support()" line can be omitted if the program
        is not going to be frozen to produce an executable.

        To fix this issue, refer to the "Safe importing of main module"
        section in https://docs.python.org/3/library/multiprocessing.html

[0m
